Workbook
Name Slicer_seller_state: #N/A

Sheet Data
A1: seller_id | B1: seller_state | C1: orders | D1: items_sold | E1: revenue | F1: avg_review_score | G1: on_time_pct
A2: 4869f7a5dfa277a7dca6462dcf3b52b2 | B2: SP | C2: 1124 | D2: 1148 | E2: 247007.06 | F2: 4.14 | G2: 89.5
A3: 7c67e1448b00f6e969d365cea6b010ab | B3: SP | C3: 973 | D3: 1355 | E3: 237806.69 | F3: 3.35 | G3: 91.1
A4: 4a3ca9315b744ce9f8e9374361493884 | B4: SP | C4: 1772 | D4: 1949 | E4: 231220.43 | F4: 3.83 | G4: 90.3
A5: 53243585a1d6dc2643021fd1853d8905 | B5: BA | C5: 348 | D5: 400 | E5: 230797.02 | F5: 4.13 | G5: 97
A6: fa1c13f2614d7b5c4749cbc52fecda94 | B6: SP | C6: 578 | D6: 579 | E6: 200833.5 | F6: 4.37 | G6: 90.8
A7: da8622b14eb17ae2831f4ac5b9dab84a | B7: SP | C7: 1311 | D7: 1548 | E7: 184706.78 | F7: 4.07 | G7: 93.6
A8: 7e93a43ef30c4f03f38b393420bc753a | B8: SP | C8: 319 | D8: 322 | E8: 171973.55 | F8: 4.36 | G8: 95.3
A9: 1025f0e2d44d7041d6cf58b6550e0bfa | B9: SP | C9: 910 | D9: 1420 | E9: 171924.96 | F9: 3.87 | G9: 93.3
A10: 7a67c85e85bb2ce8582c35f2203ad736 | B10: SP | C10: 1145 | D10: 1155 | E10: 160278.52 | F10: 4.27 | G10: 94.8
A11: 955fee9216a65b617aa5c0531780ce60 | B11: SP | C11: 1261 | D11: 1472 | E11: 156606.48 | F11: 4.09 | G11: 93.5
A12: 6560211a19b47992c3666cc44a7e94c0 | B12: SP | C12: 1819 | D12: 1996 | E12: 148050.94 | F12: 3.95 | G12: 94.9
A13: 1f50f920176fa81dab994f9023523100 | B13: SP | C13: 1399 | D13: 1926 | E13: 141712.94 | F13: 3.99 | G13: 92.2
... A497: e3b4998c7a498169dc7bce44e6bb6277 | B497: SP | C497: 1 | D497: 1 | E497: 6929.31 | F497: 5 | G497: 100
A498: 80ceebb4ee9b31afb6c6a916a574a1e2 | B498: PR | C498: 1 | D498: 1 | E498: 6922.21 | F498: NULL | G498: 0
A499: e9d99831abad74458942f21e16f33f92 | B499: SP | C499: 130 | D499: 149 | E499: 6916.06 | F499: 3.91 | G499: 90.6
A500: e8b4225284fbb02d16f200513f1f395d | B500: SP | C500: 30 | D500: 30 | E500: 6912.6 | F500: 4.3 | G500: 90
A501: 6f892e20a171e98efe17fdb971ff319b | B501: SP | C501: 41 | D501: 50 | E501: 6906.49 | F501: 3.9 | G501: 92
A502: 50c9975695009e5e6473912e83a6d1da | B502: MG | C502: 50 | D502: 68 | E502: 6883.95 | F502: 3.99 | G502: 89.7
A503: b2479f944e1b90cf8a5de1bbfde284d6 | B503: SP | C503: 101 | D503: 129 | E503: 6874.23 | F503: 3.35 | G503: 88.4
A504: 0bf0150d5b9d60d9cd2906003332f085 | B504: SP | C504: 39 | D504: 62 | E504: 6872.34 | F504: 3.71 | G504: 85.5
A505: 91f848e9f4be368f4318775aac733370 | B505: SP | C505: 60 | D505: 70 | E505: 6862.49 | F505: 4.37 | G505: 98.6
A506: bacb1f0ed56ad24198f5810d2b3fe9a5 | B506: SP | C506: 38 | D506: 38 | E506: 6847.7 | F506: 4.32 | G506: 97.4
A507: dfc5fb7259bb2b599ca565e6e9448f0f | B507: SP | C507: 33 | D507: 34 | E507: 6845.98 | F507: 4.12 | G507: 94.1
A508: abe021b01ba992245271b9aa422032df | B508: PR | C508: 2 | D508: 2 | E508: 6837.24 | F508: 3.5 | G508: 100
A509: b6d44737c043328708f6749c2dbe50bd | B509: SP | C509: 61 | D509: 79 | E509: 6834.01 | F509: 4.57 | G509: 94.9
A510: 3ade81dab5a172b88e1871c28ae05260 | B510: SP | C510: 28 | D510: 30 | E510: 6821.59 | F510: 4.24 | G510: 90
... A2869: 2c54051840f19eca309a5423cf22df36 | B2869: PR | C2869: 2 | D2869: 2 | E2869: 52.27 | F2869: 4.5 | G2869: 100
A2870: 4e2627090e6e5b9fabba883a37897683 | B2870: MG | C2870: 1 | D2870: 1 | E2870: 51.62 | F2870: NULL | G2870: 100
A2871: c161d1327ebc3a156c09582ab2f59f6c | B2871: SP | C2871: 2 | D2871: 2 | E2871: 51.55 | F2871: 4 | G2871: 100
A2872: 9200e6ce317b67196b6b0bad4d4bd567 | B2872: RJ | C2872: 1 | D2872: 1 | E2872: 51.42 | F2872: 3 | G2872: 100
A2873: fedaedd3ca31d56ab33e92035e4b361c | B2873: RJ | C2873: 1 | D2873: 1 | E2873: 50.86 | F2873: 4 | G2873: 100
A2874: 999f6d9a1c7c81f43be44c6b7d076210 | B2874: SP | C2874: 2 | D2874: 2 | E2874: 50.83 | F2874: 4.5 | G2874: 100
A2875: 630008e0f062605a415d694489f6f82e | B2875: SP | C2875: 1 | D2875: 1 | E2875: 50.7 | F2875: 5 | G2875: 100
A2876: c716e0b86ed568878475b60fbb6323ad | B2876: SP | C2876: 1 | D2876: 1 | E2876: 50.23 | F2876: 5 | G2876: 100
A2877: 5a32c398a06c345440bf2a683b017ad3 | B2877: RJ | C2877: 1 | D2877: 1 | E2877: 50.13 | F2877: 5 | G2877: 100
A2878: baeda7047354773262ba2405f97038ba | B2878: SP | C2878: 1 | D2878: 1 | E2878: 50.1 | F2878: 5 | G2878: 100
A2879: e0b162a693bc7f9eab00f783a31d60ea | B2879: RS | C2879: 1 | D2879: 1 | E2879: 49.69 | F2879: 5 | G2879: 100
A2880: 6561d6bf844e464b4019442692b40e02 | B2880: SP | C2880: 1 | D2880: 1 | E2880: 49.45 | F2880: 5 | G2880: 100
A2881: cb162c8eef257253782d245c08d9097c | B2881: SP | C2881: 1 | D2881: 1 | E2881: 49.12 | F2881: 5 | G2881: 100
...

Sheet States
A1: AC | B1: Acre | E1: Threshold | F1: Tier
A2: AL | B2: Alagoas | E2: 0 | F2: Bronze
A3: AM | B3: Amazonas | E3: 25000 | F3: Silver
A4: AP | B4: Amapá | E4: 75000 | F4: Gold
A5: BA | B5: Bahia | E5: 150000 | F5: Platinum
A6: CE | B6: Ceará
A7: DF | B7: Distrito Federal
A8: ES | B8: Espírito Santo
A9: GO | B9: Goiás
A10: MA | B10: Maranhão
A11: MG | B11: Minas Gerais
A12: MS | B12: Mato Grosso do Sul
A13: MT | B13: Mato Grosso
A14: PA | B14: Pará
A15: PB | B15: Paraíba
A16: PE | B16: Pernambuco
A17: PI | B17: Piauí
... A27: TO | B27: Tocantins

Sheet Monthly
A1: month_year | B1: orders | C1: revenue
A2: 2016-09 | B2: 1 | C2: 143
A3: 2016-10 | B3: 265 | C3: 46491
A4: 2016-12 | B4: 1 | C4: 20
A5: 2017-01 | B5: 750 | C5: 127482
A6: 2017-02 | B6: 1653 | C6: 271239
A7: 2017-03 | B7: 2546 | C7: 414331
A8: 2017-04 | B8: 2303 | C8: 390812
A9: 2017-05 | B9: 3546 | C9: 566851
A10: 2017-06 | B10: 3135 | C10: 490050
A11: 2017-07 | B11: 3872 | C11: 566299
A12: 2017-08 | B12: 4193 | C12: 645832
A13: 2017-09 | B13: 4150 | C13: 701077
... A24: 2018-08 | B24: 6351 | C24: 985492

Sheet Matrix
A1: customer_state | B1: 2016 | C1: 2017 | D1: 2018
A2: SP | B2: 13703 | C2: 2428003 | D2: 3327997 | F2: Year | G2: 2017
A3: RJ | B3: 9044 | C3: 1012943 | D3: 1033415 | F3: State | G3: SP
A4: MG | B4: 4937 | C4: 825061 | D4: 988893 | F4: HLOOKUP | G4: =HLOOKUP($G$2,$A$1:$D$28,MATCH($G$3,$A$1:$A$28,0),0) -> 2428003
A5: RS | B5: 2898 | C5: 411077 | D5: 447497 | F5: INDEX/MATCH | G5: =INDEX($B$2:$D$28,MATCH($G$3,$A$2:$A$28,0),MATCH($G$2,$B$1:$D$1,0)) -> 2428003
A6: PR | B6: 2495 | C6: 336301 | D6: 442913
A7: BA | B7: 321 | C7: 269390 | D7: 321427
A8: SC | B8: 2501 | C8: 260145 | D8: 332482
A9: GO | B9: 1056 | C9: 156980 | D9: 176176
A10: DF | B10: 1200 | C10: 151659 | D10: 193265
A11: PE | B11: 1544 | C11: 142142 | D11: 165286
A12: ES | B12: 992 | C12: 137775 | D12: 178891
A13: CE | B13: 1885 | C13: 132350 | D13: 132201
A14: PA | B14: 1283 | C14: 106518 | D14: 104222
A15: MT | B15: 101 | C15: 88809 | D15: 92314
A16: MA | B16: 999 | C16: 73389 | D16: 73415
A17: PB | B17: 75 | C17: 60608 | D17: 77155
A18: MS | B18: NULL | C18: 59897 | D18: 74471
A19: AL | B19: 77 | C19: 50873 | D19: 43223
A20: RN | B20: 881 | C20: 43425 | D20: 56409
A21: PI | B21: 246 | C21: 43421 | D21: 61511
A22: SE | B22: 346 | C22: 37359 | D22: 32584
A23: RO | B23: NULL | C23: 30312 | D23: 26654
A24: TO | B24: NULL | C24: 28156 | D24: 31852
A25: AC | B25: NULL | C25: 12892 | D25: 6683
A26: AM | B26: NULL | C26: 12834 | D26: 14752
A27: AP | B27: NULL | C27: 7211 | D27: 8931
A28: RR | B28: 69 | C28: 2007 | D28: 6964

Sheet Scorecard
A1: SELLER SCORECARD — TOP 20
A3: Seller ID | B3: State | C3: State Name | D3: Orders | E3: Revenue | F3: Avg Review | G3: On-Time % | H3: Rank | I3: Tier
A4: 4869f7a5dfa277a7dca6462dcf3b52b2 | B4: =_xlfn.XLOOKUP($A4,Data!$A:$A,Data!$B:$B) -> SP | C4: =VLOOKUP($B4,States!$A:$B,2,FALSE) -> São Paulo | D4: =_xlfn.XLOOKUP($A4,Data!$A:$A,Data!$C:$C) -> 1124 | E4: =_xlfn.XLOOKUP($A4,Data!$A:$A,Data!$E:$E) -> 247007.06 | F4: =_xlfn.XLOOKUP($A4,Data!$A:$A,Data!$F:$F) -> 4.14 | G4: =_xlfn.XLOOKUP($A4,Data!$A:$A,Data!$G:$G) -> 89.5 | H4: =RANK(E4,$E$4:$E$23) -> 1 | I4: =LOOKUP(E4,States!$E$2:$E$5,States!$F$2:$F$5) -> Platinum
A5: 7c67e1448b00f6e969d365cea6b010ab | B5: =_xlfn.XLOOKUP($A5,Data!$A:$A,Data!$B:$B) -> SP | C5: =VLOOKUP($B5,States!$A:$B,2,FALSE) -> São Paulo | D5: =_xlfn.XLOOKUP($A5,Data!$A:$A,Data!$C:$C) -> 973 | E5: =_xlfn.XLOOKUP($A5,Data!$A:$A,Data!$E:$E) -> 237806.69 | F5: =_xlfn.XLOOKUP($A5,Data!$A:$A,Data!$F:$F) -> 3.35 | G5: =_xlfn.XLOOKUP($A5,Data!$A:$A,Data!$G:$G) -> 91.1 | H5: =RANK(E5,$E$4:$E$23) -> 2 | I5: =LOOKUP(E5,States!$E$2:$E$5,States!$F$2:$F$5) -> Platinum
A6: 4a3ca9315b744ce9f8e9374361493884 | B6: =_xlfn.XLOOKUP($A6,Data!$A:$A,Data!$B:$B) -> SP | C6: =VLOOKUP($B6,States!$A:$B,2,FALSE) -> São Paulo | D6: =_xlfn.XLOOKUP($A6,Data!$A:$A,Data!$C:$C) -> 1772 | E6: =_xlfn.XLOOKUP($A6,Data!$A:$A,Data!$E:$E) -> 231220.43 | F6: =_xlfn.XLOOKUP($A6,Data!$A:$A,Data!$F:$F) -> 3.83 | G6: =_xlfn.XLOOKUP($A6,Data!$A:$A,Data!$G:$G) -> 90.3 | H6: =RANK(E6,$E$4:$E$23) -> 3 | I6: =LOOKUP(E6,States!$E$2:$E$5,States!$F$2:$F$5) -> Platinum
A7: 53243585a1d6dc2643021fd1853d8905 | B7: =_xlfn.XLOOKUP($A7,Data!$A:$A,Data!$B:$B) -> BA | C7: =VLOOKUP($B7,States!$A:$B,2,FALSE) -> Bahia | D7: =_xlfn.XLOOKUP($A7,Data!$A:$A,Data!$C:$C) -> 348 | E7: =_xlfn.XLOOKUP($A7,Data!$A:$A,Data!$E:$E) -> 230797.02 | F7: =_xlfn.XLOOKUP($A7,Data!$A:$A,Data!$F:$F) -> 4.13 | G7: =_xlfn.XLOOKUP($A7,Data!$A:$A,Data!$G:$G) -> 97 | H7: =RANK(E7,$E$4:$E$23) -> 4 | I7: =LOOKUP(E7,States!$E$2:$E$5,States!$F$2:$F$5) -> Platinum
A8: fa1c13f2614d7b5c4749cbc52fecda94 | B8: =_xlfn.XLOOKUP($A8,Data!$A:$A,Data!$B:$B) -> SP | C8: =VLOOKUP($B8,States!$A:$B,2,FALSE) -> São Paulo | D8: =_xlfn.XLOOKUP($A8,Data!$A:$A,Data!$C:$C) -> 578 | E8: =_xlfn.XLOOKUP($A8,Data!$A:$A,Data!$E:$E) -> 200833.5 | F8: =_xlfn.XLOOKUP($A8,Data!$A:$A,Data!$F:$F) -> 4.37 | G8: =_xlfn.XLOOKUP($A8,Data!$A:$A,Data!$G:$G) -> 90.8 | H8: =RANK(E8,$E$4:$E$23) -> 5 | I8: =LOOKUP(E8,States!$E$2:$E$5,States!$F$2:$F$5) -> Platinum
A9: da8622b14eb17ae2831f4ac5b9dab84a | B9: =_xlfn.XLOOKUP($A9,Data!$A:$A,Data!$B:$B) -> SP | C9: =VLOOKUP($B9,States!$A:$B,2,FALSE) -> São Paulo | D9: =_xlfn.XLOOKUP($A9,Data!$A:$A,Data!$C:$C) -> 1311 | E9: =_xlfn.XLOOKUP($A9,Data!$A:$A,Data!$E:$E) -> 184706.78 | F9: =_xlfn.XLOOKUP($A9,Data!$A:$A,Data!$F:$F) -> 4.07 | G9: =_xlfn.XLOOKUP($A9,Data!$A:$A,Data!$G:$G) -> 93.6 | H9: =RANK(E9,$E$4:$E$23) -> 6 | I9: =LOOKUP(E9,States!$E$2:$E$5,States!$F$2:$F$5) -> Platinum
A10: 7e93a43ef30c4f03f38b393420bc753a | B10: =_xlfn.XLOOKUP($A10,Data!$A:$A,Data!$B:$B) -> SP | C10: =VLOOKUP($B10,States!$A:$B,2,FALSE) -> São Paulo | D10: =_xlfn.XLOOKUP($A10,Data!$A:$A,Data!$C:$C) -> 319 | E10: =_xlfn.XLOOKUP($A10,Data!$A:$A,Data!$E:$E) -> 171973.55 | F10: =_xlfn.XLOOKUP($A10,Data!$A:$A,Data!$F:$F) -> 4.36 | G10: =_xlfn.XLOOKUP($A10,Data!$A:$A,Data!$G:$G) -> 95.3 | H10: =RANK(E10,$E$4:$E$23) -> 7 | I10: =LOOKUP(E10,States!$E$2:$E$5,States!$F$2:$F$5) -> Platinum
A11: 1025f0e2d44d7041d6cf58b6550e0bfa | B11: =_xlfn.XLOOKUP($A11,Data!$A:$A,Data!$B:$B) -> SP | C11: =VLOOKUP($B11,States!$A:$B,2,FALSE) -> São Paulo | D11: =_xlfn.XLOOKUP($A11,Data!$A:$A,Data!$C:$C) -> 910 | E11: =_xlfn.XLOOKUP($A11,Data!$A:$A,Data!$E:$E) -> 171924.96 | F11: =_xlfn.XLOOKUP($A11,Data!$A:$A,Data!$F:$F) -> 3.87 | G11: =_xlfn.XLOOKUP($A11,Data!$A:$A,Data!$G:$G) -> 93.3 | H11: =RANK(E11,$E$4:$E$23) -> 8 | I11: =LOOKUP(E11,States!$E$2:$E$5,States!$F$2:$F$5) -> Platinum
A12: 7a67c85e85bb2ce8582c35f2203ad736 | B12: =_xlfn.XLOOKUP($A12,Data!$A:$A,Data!$B:$B) -> SP | C12: =VLOOKUP($B12,States!$A:$B,2,FALSE) -> São Paulo | D12: =_xlfn.XLOOKUP($A12,Data!$A:$A,Data!$C:$C) -> 1145 | E12: =_xlfn.XLOOKUP($A12,Data!$A:$A,Data!$E:$E) -> 160278.52 | F12: =_xlfn.XLOOKUP($A12,Data!$A:$A,Data!$F:$F) -> 4.27 | G12: =_xlfn.XLOOKUP($A12,Data!$A:$A,Data!$G:$G) -> 94.8 | H12: =RANK(E12,$E$4:$E$23) -> 9 | I12: =LOOKUP(E12,States!$E$2:$E$5,States!$F$2:$F$5) -> Platinum
A13: 955fee9216a65b617aa5c0531780ce60 | B13: =_xlfn.XLOOKUP($A13,Data!$A:$A,Data!$B:$B) -> SP | C13: =VLOOKUP($B13,States!$A:$B,2,FALSE) -> São Paulo | D13: =_xlfn.XLOOKUP($A13,Data!$A:$A,Data!$C:$C) -> 1261 | E13: =_xlfn.XLOOKUP($A13,Data!$A:$A,Data!$E:$E) -> 156606.48 | F13: =_xlfn.XLOOKUP($A13,Data!$A:$A,Data!$F:$F) -> 4.09 | G13: =_xlfn.XLOOKUP($A13,Data!$A:$A,Data!$G:$G) -> 93.5 | H13: =RANK(E13,$E$4:$E$23) -> 10 | I13: =LOOKUP(E13,States!$E$2:$E$5,States!$F$2:$F$5) -> Platinum
A14: 6560211a19b47992c3666cc44a7e94c0 | B14: =_xlfn.XLOOKUP($A14,Data!$A:$A,Data!$B:$B) -> SP | C14: =VLOOKUP($B14,States!$A:$B,2,FALSE) -> São Paulo | D14: =_xlfn.XLOOKUP($A14,Data!$A:$A,Data!$C:$C) -> 1819 | E14: =_xlfn.XLOOKUP($A14,Data!$A:$A,Data!$E:$E) -> 148050.94 | F14: =_xlfn.XLOOKUP($A14,Data!$A:$A,Data!$F:$F) -> 3.95 | G14: =_xlfn.XLOOKUP($A14,Data!$A:$A,Data!$G:$G) -> 94.9 | H14: =RANK(E14,$E$4:$E$23) -> 11 | I14: =LOOKUP(E14,States!$E$2:$E$5,States!$F$2:$F$5) -> Gold
A15: 1f50f920176fa81dab994f9023523100 | B15: =_xlfn.XLOOKUP($A15,Data!$A:$A,Data!$B:$B) -> SP | C15: =VLOOKUP($B15,States!$A:$B,2,FALSE) -> São Paulo | D15: =_xlfn.XLOOKUP($A15,Data!$A:$A,Data!$C:$C) -> 1399 | E15: =_xlfn.XLOOKUP($A15,Data!$A:$A,Data!$E:$E) -> 141712.94 | F15: =_xlfn.XLOOKUP($A15,Data!$A:$A,Data!$F:$F) -> 3.99 | G15: =_xlfn.XLOOKUP($A15,Data!$A:$A,Data!$G:$G) -> 92.2 | H15: =RANK(E15,$E$4:$E$23) -> 12 | I15: =LOOKUP(E15,States!$E$2:$E$5,States!$F$2:$F$5) -> Gold
... A23: edb1ef5e36e0c8cd84eb3c9b003e486d | B23: =_xlfn.XLOOKUP($A23,Data!$A:$A,Data!$B:$B) -> RJ | C23: =VLOOKUP($B23,States!$A:$B,2,FALSE) -> Rio de Janeiro | D23: =_xlfn.XLOOKUP($A23,Data!$A:$A,Data!$C:$C) -> 165 | E23: =_xlfn.XLOOKUP($A23,Data!$A:$A,Data!$E:$E) -> 83031.14 | F23: =_xlfn.XLOOKUP($A23,Data!$A:$A,Data!$F:$F) -> 4.45 | G23: =_xlfn.XLOOKUP($A23,Data!$A:$A,Data!$G:$G) -> 93.1 | H23: =RANK(E23,$E$4:$E$23) -> 20 | I23: =LOOKUP(E23,States!$E$2:$E$5,States!$F$2:$F$5) -> Gold

Sheet Dashboard
A3: Row Labels | B3: Sum of revenue
A4: AM | B4: 1258.8
A5: BA | B5: 297146.93
A6: CE | B6: 23724.05
A7: DF | B7: 112892.78
A8: ES | B8: 58853.49
A9: GO | B9: 77089.48
A10: MA | B10: 48169.5
A11: MG | B11: 1184427.5
A12: MS | B12: 9750.65
A13: MT | B13: 21623.67
A14: PA | B14: 1393.11
A15: PB | B15: 17844.43
... A26: Grand Total | B26: 15419774
A30: Row Labels | B30: Average of avg_review_score
A31: AM | B31: 2.33
A32: BA | B32: 4.2377778
A33: CE | B33: 3.795
A34: DF | B34: 4.058
A35: ES | B35: 4.3831818
A36: GO | B36: 4.1876923
A37: MA | B37: 4.02
A38: MG | B38: 4.1908511
A39: MS | B39: 4.29
A40: MT | B40: 4.2225
A41: PA | B41: 4.5
A42: PB | B42: 4.305
... A53: Grand Total | B53: 4.150661
